<?xml version="1.0" ?>
<!-- =================================================================================== -->
<!-- |    This document was autogenerated by xacro from src/cart_pole/cart_pole_bringup/urdf/cart_pole.urdf.xacro | -->
<!-- |    EDITING THIS FILE BY HAND IS NOT RECOMMENDED                                 | -->
<!-- =================================================================================== -->
<robot name="cart_pole">
  <link name="world"/>
  <link name="slide_bar">
    <visual>
      <origin xyz="0 0 0"/>
      <geometry>
        <mesh filename="/workspaces/reinforcement_learning_playground/install/cart_pole_bringup/share/cart_pole_bringup/meshes/slide_bar.dae"/>
      </geometry>
    </visual>
    <collision>
      <origin rpy="0 0 1.5707963267948966" xyz="0.025 -0.1 0"/>
      <geometry>
        <box size="1.8 0.1 0.05"/>
      </geometry>
    </collision>
    <inertial>
      <origin rpy="0 0 1.5707963267948966" xyz="0.025 -0.1 0"/>
      <mass value="10"/>
      <inertia ixx="0.01041666666666667" ixy="0.0" ixz="0.0" iyy="2.7020833333333334" iyz="0.0" izz="2.7083333333333335"/>
    </inertial>
  </link>
  <link name="cart">
    <visual>
      <origin xyz="0 0 0"/>
      <geometry>
        <mesh filename="/workspaces/reinforcement_learning_playground/install/cart_pole_bringup/share/cart_pole_bringup/meshes/cart.dae"/>
      </geometry>
    </visual>
    <collision>
      <origin xyz="0.04 0 0"/>
      <geometry>
        <box size="0.1 0.16 0.11"/>
      </geometry>
    </collision>
    <inertial>
      <mass value="1.006"/>
      <inertia ixx="0.001999325" ixy="0.00000769" ixz="0.000002051" iyy="0.00218888" iyz="0.000001714" izz="0.002943291"/>
    </inertial>
  </link>
  <link name="pole_with_holder">
    <visual>
      <origin rpy="0 0 0" xyz="0 0 0"/>
      <geometry>
        <mesh filename="/workspaces/reinforcement_learning_playground/install/cart_pole_bringup/share/cart_pole_bringup/meshes/pole_with_holder.dae"/>
      </geometry>
    </visual>
    <collision>
      <origin rpy="1.5707963267948966 0 0" xyz="0.04 0.485 0"/>
      <geometry>
        <cylinder length="1.0" radius="0.01"/>
      </geometry>
    </collision>
    <inertial>
      <origin rpy="0 0 0" xyz="0.039298 0.435057 0"/>
      <mass value="0.455"/>
      <inertia ixx="0.044100482" ixy="-0.000237859" ixz="-0.000004" iyy="0.000040196" iyz="-0.000037" izz="0.044096759"/>
    </inertial>
  </link>
  <joint name="slider_to_pole_with_holder" type="revolute">
    <axis xyz="1 0 0"/>
    <origin rpy="1.5707963267948966 0 0" xyz="0.08 0 0"/>
    <parent link="cart"/>
    <child link="pole_with_holder"/>
    <limit effort="10000" lower="-1.4" upper="1.4" velocity="1000"/>
  </joint>
  <joint name="world_to_base" type="fixed">
    <origin rpy="0 0 3.141592653589793" xyz="0 0 1"/>
    <parent link="world"/>
    <child link="slide_bar"/>
  </joint>
  <joint name="slider_to_cart" type="prismatic">
    <axis xyz="0 -1 0"/>
    <origin xyz="0.09 0.0 0.004"/>
    <parent link="slide_bar"/>
    <child link="cart"/>
    <limit effort="10000" lower="-0.568057" upper="0.7749429999999999" velocity="1000"/>
    <dynamics damping="0.05"/>
  </joint>
  <gazebo reference="cart">
    <visual>
      <material>
        <ambient>0 0 0.8 1</ambient>
        <diffuse>0 0 0.8 1</diffuse>
        <specular>0 0 0.8 1</specular>
      </material>
    </visual>
  </gazebo>
  <gazebo reference="pole_with_holder">
    <visual>
      <material>
        <ambient>0.8 0 0 1</ambient>
        <diffuse>0.8 0 0 1</diffuse>
        <specular>0.8 0 0 1</specular>
      </material>
    </visual>
  </gazebo>
  <gazebo>
    <plugin filename="gz-sim-joint-controller-system" name="gz::sim::systems::JointController">
      <joint_name>slider_to_cart</joint_name>
      <use_force_commands>true</use_force_commands>
      <topic>effort_cmd</topic>
    </plugin>
    <plugin filename="gz-sim-joint-state-publisher-system" name="gz::sim::systems::JointStatePublisher">
      <topic>joint_states</topic>
      <joint_name>slider_to_cart</joint_name>
      <joint_name>slider_to_pole_with_holder</joint_name>
    </plugin>
  </gazebo>
</robot>
